File: Session 2: Intro to Numerical Methods/data/MVH-30000OE-50K.csv
Time Stamp (sec),Temperature (K),Magnetic Field (Oe),Moment (emu),M. Std. Err. (emu)
3748222422.105,50.1864700317383,-0.00221176794730127,,
3748222491.5065,50.1801319122314,250.016876220703,-0.389600963726601,5.86894276642928E-5
3748222555.5065,50.1740646362305,550.317138671875,-0.454761187484272,0.000407833216447913
3748222620.3465,50.1696853637695,849.988494873047,-0.379186499842907,0.000170978486215857
3748222686.313,50.1650943756103,1150.10906982422,-0.323804446333182,0.000102769650076463
3748222750.213,50.160099029541,1450.10296630859,-0.291011259654138,0.000113868139371794
3748222816.1995,50.1574153900146,1750.25134277344,-0.266581055136296,0.000122504838330036
3748222882.1275,50.153715133667,2050.17590332031,-0.247365468411849,8.87683595474412E-5
3748222948.1175,50.1505718231201,2350.05932617187,-0.232769584218089,6.84824219781494E-5
3748223014.069,50.1481914520264,2650.13146972656,-0.221454962155304,7.59457767423128E-5
3748223093.008,50.148078918457,2900.13439941406,-0.212706495940566,6.97260556268006E-5
3748223157.9855,50.1444797515869,3200.19299316406,-0.204671588026716,6.28208148823564E-5
3748223230.275,50.1412162780762,3500.01867675781,-0.198020187643641,5.63732233356226E-5
3748223294.957,50.1390743255615,3799.98486328125,-0.191695084437872,6.80127794079175E-5
3748223360.819,50.1364040374756,4100.158203125,-0.185756921634833,4.95793094489024E-5
3748223426.7695,50.1355781555176,4400.3203125,-0.181087793081344,4.30363259273466E-5
3748223493.755,50.1335525512695,4699.93212890625,-0.176206899150283,3.1426909016249E-5
3748223560.6525,50.1318016052246,5000.0849609375,-0.172923074144406,3.54262367985582E-5
3748223625.6645,50.1306591033936,5300.16625976562,-0.16956885014143,5.71096504961533E-5
3748223704.595,50.1317844390869,5549.99169921875,-0.166126695692463,3.34394824312816E-5
3748223771.522,50.1337966918945,5849.95556640625,-0.162778359999127,2.30145496577435E-5
3748223838.4335,50.1274585723877,6149.93579101562,-0.160403260840635,2.03454283923771E-5
3748223904.3485,50.1254730224609,6450.04956054687,-0.158106579230232,2.73389099632078E-5
3748223971.3245,50.1248512268066,6749.94409179688,-0.155635943918676,2.73462680597676E-5
3748224037.325,50.1233825683594,7050.15185546875,-0.153230129603483,2.69480313774935E-5
3748224104.215,50.1217079162598,7349.9755859375,-0.150373065690048,2.3473587577512E-5
3748224169.1715,50.1219882965088,7650.23657226563,-0.149089817029463,4.19914637692025E-5
3748224234.155,50.1203289031982,7950.17724609375,-0.147162070271698,4.85133901712535E-5
3748224313.1375,50.1224555969238,8199.9130859375,-0.145538111002719,4.77826093533385E-5
3748224380.0145,50.1210041046143,8500.236328125,-0.144778501307439,4.16928836278134E-5
3748224446.039,50.1190128326416,8800.1357421875,-0.143329039822834,7.58243902154969E-5
3748224512.987,50.1175632476807,9100.279296875,-0.14118234187249,3.60504400041798E-5
3748224580.974,50.1167373657227,9400.02734375,-0.139606243220604,3.32615203107803E-5
3748224647.9,50.1165390014648,9700.27490234375,-0.138777088581446,5.78796702297312E-5
3748224714.752,50.1173896789551,10000.0126953125,-0.137116531258087,2.8965412486397E-5
3748224782.7425,50.1151504516602,10300.0249023438,-0.135686326363715,3.55269850206126E-5
3748224850.7655,50.1157150268555,10600.0024414062,-0.134216562612811,3.38619683452412E-5
3748224929.6085,50.1176147460937,10850.2841796875,-0.134176382421083,4.29249248782324E-5
3748224995.5585,50.1165828704834,11149.9741210938,-0.13217083941169,3.24615543452484E-5
3748225063.5465,50.1195945739746,11450.0185546875,-0.131598403967651,3.48256481643742E-5
3748225131.5035,50.1141757965088,11750.0336914062,-0.130374010076383,5.17536670852075E-5
3748225201.4455,50.1133689880371,12050.1723632812,-0.129959820206956,3.64411991292641E-5
3748225269.3995,50.1128234863281,12350.01171875,-0.128562251529234,3.37294560365653E-5
3748225337.3305,50.1125335693359,12649.9428710938,-0.127471830493597,3.27212402092587E-5
3748225405.257,50.112979888916,12949.962890625,-0.126535001753847,3.0979717592669E-5
3748225473.236,50.1131057739258,13250.2309570312,-0.126522864172171,3.71834554090819E-5
3748225553.1675,50.1151142120361,13500.0166015625,-0.12532240422892,2.05430064299951E-5
3748225621.0925,50.1140613555908,13799.9321289062,-0.122888509775153,5.35806174157502E-5
3748225689.0625,50.1150417327881,14100.3090820312,-0.123946793030242,3.9699370481161E-5
3748225757.024,50.1112422943115,14400.1391601562,-0.122793490163123,3.35588835870539E-5
3748225826.9695,50.1110687255859,14700.1928710938,-0.122961725412702,3.36952051125829E-5
3748225896.8945,50.1110076904297,15000.0043945313,-0.121940431374792,1.34605092869298E-5
3748225965.943,50.1104698181152,15300.0053710938,-0.12088585615259,2.34634639632385E-5
3748226035.8115,50.1109790802002,15600.3608398438,-0.120531681951697,3.73783068881317E-5
3748226105.714,50.1111698150635,15900.2509765625,-0.119960638292829,3.58355313796367E-5
3748226185.7345,50.1134395599365,16150.0576171875,-0.118434468970157,5.7979579516546E-5
3748226254.6535,50.1126098632812,16450.150390625,-0.118283570566469,4.46316338704796E-5
3748226322.62,50.109748840332,16749.81640625,-0.117770731934411,2.91929140372294E-5
3748226391.5315,50.1097068786621,17049.9658203125,-0.116882533344752,4.55823423141843E-5
3748226460.486,50.1095638275146,17350.287109375,-0.116018154245729,3.8965962984222E-5
3748226530.359,50.108793258667,17650.1533203125,-0.11487046947885,4.32707616944906E-5
3748226599.3665,50.1095752716064,17949.974609375,-0.114455588381619,3.96453794513102E-5
3748226668.284,50.108922958374,18250.099609375,-0.113545527897201,3.75622353435385E-5
3748226738.231,50.1080951690674,18550.140625,-0.112933558696598,4.00610479999395E-5
3748226821.2185,50.1118679046631,18800.083984375,-0.112691794608018,3.98067035048364E-5
3748226890.1015,50.1099815368652,19100.166015625,-0.111647034659481,4.67531088630235E-5
3748226958.177,50.1106967926025,19400.1064453125,-0.110869251899111,4.23086455594072E-5
3748227028.996,50.1087989807129,19700.1298828125,-0.110577498833147,5.18721385103868E-5
3748227098.9735,50.1097354888916,20000.091796875,-0.109994109164026,4.26834654827709E-5
3748227168.975,50.1088466644287,20300.01171875,-0.108875105776951,4.34507367240326E-5
3748227239.88,50.1096458435059,20600.1005859375,-0.109153575894184,4.69895512679637E-5
3748227309.7575,50.1082668304443,20899.9677734375,-0.107756942379833,4.98325355852152E-5
3748227393.157,50.1064453125,21150.005859375,-0.100795910683719,3.86117329377057E-5
3748227464.749,50.1108531951904,21450.05859375,-0.106782422787134,3.55747278077506E-5
3748227534.655,50.1100997924805,21749.875,-0.105637480857365,3.55929436424596E-5
3748227603.6915,50.1091747283936,22049.9423828125,-0.105091621296616,5.23811208264806E-5
3748227672.6165,50.109354019165,22349.7958984375,-0.105165488164718,3.85584010306331E-5
3748227741.494,50.1090564727783,22650.041015625,-0.104965633821349,3.01336940783021E-5
3748227811.411,50.1087226867676,22950.05078125,-0.10413765488171,2.46472897587856E-5
3748227882.443,50.1084823608398,23249.9775390625,-0.10327384399983,1.91603234678898E-5
3748227952.318,50.1089172363281,23550.119140625,-0.102739072606446,4.92463082778612E-5
3748228035.2925,50.1121253967285,23799.8173828125,-0.101408535219799,3.67824347431332E-5
3748228105.2305,50.1112289428711,24100.19140625,-0.101216356592638,3.3466230219807E-5
3748228175.178,50.1092109680176,24399.994140625,-0.100805305348528,3.11960703865359E-5
3748228244.1415,50.1089172363281,24699.8349609375,-0.0994583723607029,2.50628752477467E-5
3748228316.062,50.1128082275391,25000.07421875,-0.0998709362462257,3.52726370412848E-5
3748228387.0465,50.109561920166,25299.9541015625,-0.0991413011629786,3.0000959042549E-5
3748228457.994,50.1093254089355,25600.14453125,-0.098254500488206,3.39650948986068E-5
3748228528.8775,50.1092166900635,25899.869140625,-0.0971752132231669,3.77990282763156E-5
3748228616.864,50.1105842590332,26199.9921875,,
3748228686.814,50.111629486084,26450.125,-0.0969408451742299,3.32367134357911E-5
3748228758.7095,50.1087741851807,26749.9697265625,-0.0963998238225347,3.5574458327759E-5
3748228830.708,50.1093883514404,27050.130859375,-0.0954782036669503,3.94049731885691E-5
3748228902.615,50.1097545623779,27349.9853515625,-0.0947361891089535,2.64484688418651E-5
3748228973.5665,50.1097354888916,27650.2509765625,-0.0944406851841391,4.51019104231818E-5
3748229044.4745,50.1086730957031,27949.9326171875,-0.0936883805746982,4.3208831494097E-5
3748229116.494,50.1095218658447,28250.125,-0.0928830390088329,4.38134262532543E-5
3748229188.3885,50.1098079681396,28550.0947265625,-0.0925693338390158,5.36446013819691E-5
3748229271.3475,50.1122932434082,28800.1201171875,-0.0926315748138123,4.51399340523565E-5
3748229343.341,50.111307144165,29099.880859375,-0.090448235163681,3.11968774453865E-5
3748229414.2365,50.1101608276367,29399.8525390625,-0.0904359916728803,4.18893096148777E-5
3748229487.2735,50.1090488433838,29700.1650390625,-0.0900637769150953,3.72545188262661E-5
3748229559.122,50.1089649200439,30000.1162109375,-0.089754129862295,3.82029706296183E-5
3748229624.041,50.1096096038818,29700.0322265625,-0.0266337332984521,0.000100226209198915
3748229702.166,50.1096229553223,29400,-0.0278352175147873,3.38803720405948E-5
3748229792.157,50.1094608306885,29100.001953125,-0.0261318451067195,3.32579479707816E-5
3748229888.1015,50.1118450164795,28849.9931640625,-0.0276862177406241,4.2961698064771E-5
3748229977.9455,50.1104717254639,28550.021484375,-0.0267535062704782,4.03982393136084E-5
3748230067.945,50.1092758178711,28250.0185546875,-0.0269894468697869,3.5979070592448E-5
3748230157.84,50.1085472106934,27949.990234375,-0.0285213236501124,4.68462254784192E-5
3748230247.784,50.1078357696533,27649.99609375,-0.0282484543572049,2.50664645694475E-5
3748230337.71,50.1083488464355,27350.013671875,-0.0279972998596518,3.02075811659789E-5
3748230422.5255,50.1081657409668,27050.337890625,-0.0236695199067331,0.000131794413083571
3748230509.586,50.1109313964844,26800.013671875,-0.0283526751883149,3.14176907374723E-5
3748230583.35,50.1092700958252,26500.046875,-0.0254462155741575,8.89172753171564E-5
3748230657.2775,50.1079864501953,26200.2548828125,-0.0262245341457435,7.00900112328761E-5
3748230726.249,50.1079387664795,25900.203125,-0.0270583001955889,0.000117021354792163
3748230791.151,50.1078186035156,25600.2021484375,-0.0268853236957524,6.50972821222431E-5
3748230855.213,50.1076755523682,25300.2109375,-0.027516022630843,6.99825505645953E-5
3748230921.0555,50.1067562103271,25000.23828125,-0.0274891530291754,8.14492118394261E-5
3748230985.047,50.1076278686523,24700.1123046875,-0.0298184711129867,7.0361943196881E-5
3748231050.9515,50.1080646514893,24399.94921875,-0.0287224458177955,8.20022248007904E-5
3748231129.013,50.1105308532715,24150.083984375,-0.029587939558483,6.8890120726332E-5
3748231193.886,50.1096172332764,23850.19140625,-0.0292866871134792,9.78876640117157E-5
3748231259.916,50.1083507537842,23550.14453125,-0.0297623707365481,7.22519341410894E-5
3748231324.839,50.1076335906982,23250.1162109375,-0.0306510996927525,8.26979309534015E-5
3748231389.796,50.1070003509521,22949.986328125,-0.0307823860783579,7.31988028352805E-5
3748231454.6795,50.1064281463623,22650.0986328125,-0.0312093438540214,0.000104954338675544
3748231520.674,50.1070003509521,22350.0029296875,-0.0317703672908277,9.3034261096098E-5
3748231585.601,50.1066474914551,22049.849609375,-0.0317888669312161,0.000114007310092083
3748231652.518,50.1071147918701,21749.9833984375,-0.0336374373052687,5.88017742189341E-5
3748231730.8235,50.1048450469971,21499.9755859375,-0.0429065509422395,2.68444032897629E-5
3748231796.48,50.1092052459717,21199.9423828125,-0.0332260114625724,8.28700941409021E-5
3748231862.367,50.1071681976318,20900.015625,-0.0348466869683892,5.71821061221183E-5
3748231928.3605,50.1067733764648,20600.1708984375,-0.0344708844066816,7.68245465617374E-5
3748231993.258,50.1064338684082,20300.232421875,-0.0347812928605978,8.15966211231649E-5
3748232059.3745,50.1061935424805,20000.107421875,-0.0354477232198379,7.28320693318996E-5
3748232125.209,50.1065292358398,19700.1533203125,-0.0363067513385144,7.19524387580954E-5
3748232190.2415,50.1055660247803,19399.896484375,-0.0360975686104889,0.000131999067546754
3748232260.0665,50.1058464050293,19099.9140625,-0.0372722775560842,7.84055128968427E-5
3748232339.639,50.1068077087402,18800.0234375,,
3748232402.9495,50.1092700958252,18549.9189453125,-0.0384595701470624,0.000104420559137672
3748232467.8865,50.1115875244141,18250.0517578125,-0.0394946712582284,7.25285475072569E-5
3748232532.9345,50.107120513916,17950.1220703125,-0.0398908347319755,7.52838438471249E-5
3748232599.9235,50.1058120727539,17650.041015625,-0.0407445649246116,7.13604204522257E-5
3748232664.756,50.1053771972656,17350.0400390625,-0.0403487585138961,0.00011196817202709
3748232729.7745,50.1061153411865,17049.9755859375,-0.0419147126426072,6.54646379860826E-5
3748232794.7095,50.1052570343018,16750.146484375,-0.042101542691659,8.59133644465994E-5
3748232861.7195,50.1046485900879,16450.125,-0.0434231266708555,5.78000505104425E-5
3748232925.572,50.1054725646973,16150.1938476562,-0.0439665121111494,5.50716620214821E-5
3748233005.5245,50.1070232391357,15899.9306640625,-0.0436922961488055,0.000114722614354348
3748233072.4955,50.1065464019775,15600.2915039062,-0.0445510594831202,7.98124681548254E-5
3748233139.4745,50.1062545776367,15299.9428710938,-0.0449222707835781,0.000106331942431262
3748233207.383,50.1055545806885,15000.0502929687,-0.0475084624424512,5.44647914711395E-5
3748233275.2935,50.1052742004395,14700.1401367188,-0.0485186162850008,3.92377060737415E-5
3748233341.272,50.1050415039063,14399.91015625,-0.0476686803630563,9.24174996727976E-5
3748233408.2215,50.1047668457031,14099.9721679688,-0.0492757737145281,5.15340821307739E-5
3748233475.1835,50.1047115325928,13799.9301757813,-0.0489181302735513,0.000101624652949889
3748233540.133,50.1050415039063,13500.0322265625,-0.0501560441237472,8.21378036734728E-5
3748233622.1005,50.1072998046875,13250.1801757813,-0.0507138517097598,6.72184212418762E-5
3748233690.962,50.1065692901611,12950.1791992187,-0.0520182995968646,5.77229101493459E-5
3748233758.951,50.1057567596436,12650.1552734375,-0.0529731183976368,5.21850846891781E-5
3748233825.968,50.1048030853271,12350.1220703125,-0.0545040607676173,3.42632069308338E-5
3748233893.8745,50.1041698455811,12049.9458007813,-0.0551528397145027,4.65320904561473E-5
3748233959.8365,50.1036434173584,11750.2861328125,-0.0546641135277246,4.84958631789526E-5
3748234027.7675,50.1041698455811,11450.30859375,-0.0558586420847674,5.38036528566305E-5
3748234094.7405,50.1043071746826,11149.8979492187,-0.0564725663728338,8.07583157373468E-5
3748234162.652,50.1039657592773,10850.251953125,-0.0577482424323579,6.11624177715945E-5
3748234241.64,50.1065521240234,10599.947265625,-0.058998842757404,6.28693331233064E-5
3748234307.5665,50.105978012085,10300.1953125,-0.0597865256754466,8.04285972431329E-5
3748234372.514,50.1044330596924,9999.9873046875,-0.0603847667397055,6.29939578352676E-5
3748234439.455,50.1047554016113,9699.97509765625,-0.0618408367754624,4.51878761807538E-5
3748234505.3695,50.1041870117188,9400.22119140625,-0.0617560007271112,6.1213627239531E-5
3748234569.3555,50.103422164917,9100.2978515625,-0.0615930291941944,0.000113350111665671
3748234635.334,50.1031723022461,8800.154296875,-0.0639719867483315,4.68408914112589E-5
3748234700.32,50.1035480499268,8500.09814453125,-0.0649426730518972,4.96171118466534E-5
3748234764.306,50.1037979125977,8200.05859375,-0.0648943555017184,9.17812398708509E-5
3748234846.137,50.1064262390137,7950.24169921875,-0.0660438441993267,6.06247960596748E-5
3748234913.0845,50.1042881011963,7650.19946289063,-0.0669024883851121,5.61745886252603E-5
3748234980.038,50.1040210723877,7349.95703125,-0.0670985487022376,8.95783675871241E-5
3748235044.9815,50.1032180786133,7050.01831054687,-0.0686269853315274,6.07621182223473E-5
3748235112.9575,50.1035480499268,6749.94409179688,-0.0701209942166385,3.96778954636539E-5
3748235179.9735,50.1027221679687,6449.95239257812,-0.0703338928009919,6.00235052699406E-5
3748235246.915,50.1032314300537,6150.140625,-0.0708816359305575,5.3290428156183E-5
3748235313.795,50.1031665802002,5849.93725585938,-0.0714303877382961,6.93853610484004E-5
3748235380.7565,50.1026458740234,5550.00561523438,-0.072600405359201,5.60898021064744E-5
3748235462.6685,50.1053104400635,5300.06713867188,-0.0729165312238941,5.88625915853507E-5
3748235529.629,50.104944229126,5000.33154296875,-0.0734293347851142,5.11729816164692E-5
3748235595.614,50.1037158966064,4700.1142578125,-0.0740868671946902,5.86858307381223E-5
3748235661.538,50.1024780273438,4400.13623046875,-0.0749027024406871,5.32219555245201E-5
3748235727.484,50.1029796600342,4100.10302734375,-0.075571690002979,5.09463911033437E-5
3748235793.4875,50.1026477813721,3800.13671875,-0.076088786151699,4.61658049444687E-5
3748235858.331,50.1015529632568,3500.15905761719,-0.0763916828400308,5.64542634965099E-5
3748235923.322,50.1027126312256,3200.20910644531,-0.0766106224687885,5.2246939353575E-5
3748235989.3,50.1031475067139,2900.20593261719,-0.0765501040268299,5.31310770549216E-5
3748236068.1795,50.1030044555664,2650.17529296875,-0.0758294528297143,8.61056881989182E-5
3748236133.1885,50.1041164398193,2350.0087890625,-0.076313625636062,5.88758585820851E-5
3748236198.161,50.1035709381103,2050.15979003906,-0.0751361233288252,5.52045953633993E-5
3748236263.0685,50.1026401519775,1750.02545166016,-0.0738470509340742,6.10684647908399E-5
3748236328.9795,50.1029987335205,1450.16052246094,-0.0707778627807703,6.47476403153839E-5
3748236395.024,50.1020736694336,1150.41784667969,-0.0640802212264175,0.000144302108413251
3748236459.964,50.1020908355713,850.004577636719,-0.0576988158514881,7.91379643635647E-5
3748236524.8785,50.1021862030029,550.167388916016,-0.039421830783113,0.000101023276023511
3748236599.1195,50.102388381958,249.989227294922,0.00804147696008887,9.88229748198797E-5
3748236680.123,50.0998516082764,-0.00681964948307723,0.147852181386057,2.6496000562853E-5
3748236744.7205,50.1037826538086,-299.970764160156,0.433935933640933,0.000116385207918437
3748236808.6785,50.1042881011963,-599.810272216797,0.44586684053671,0.000428215022762036
3748236869.5935,50.1026229858398,-899.7626953125,0.37362037477502,0.000276488578237384
3748236929.5715,50.1012725830078,-1199.89483642578,0.32423646791215,0.0002474634322828
3748236989.539,50.1020126342773,-1499.93475341797,0.290776307752332,0.000242347891257425
3748237049.481,50.1014995574951,-1799.99768066406,0.267689993679061,0.000259502890253975
3748237111.506,50.1019763946533,-2100.07666015625,0.248911436890633,0.000212043780763675
3748237173.449,50.1013679504395,-2400.12377929687,0.234620400484196,0.000193768110233262
3748237234.399,50.1013488769531,-2700.38940429687,0.222740441605892,0.000167932621003412
3748237311.313,50.1037750244141,-2950.11352539063,0.213120936128399,9.63561717790835E-5
3748237376.262,50.1037635803223,-3250.14208984375,0.205179806137548,8.03685256377182E-5
3748237444.4055,50.1034469604492,-3550.06665039063,0.197537150492069,6.10465819773509E-5
3748237509.126,50.102783203125,-3850.02136230469,0.191916082259753,6.10245429262858E-5
3748237574.1305,50.1029739379883,-4150.10717773438,0.185359078836497,4.27244038120015E-5
3748237638.995,50.1019248962402,-4450.01611328125,0.181654973029583,5.13870149444197E-5
3748237703.972,50.1017742156982,-4750.24291992188,0.177503857877734,5.66077551982083E-5
3748237768.97,50.1015701293945,-5049.98559570313,0.173645986419439,4.38378759199602E-5
3748237833.8465,50.1016311645508,-5350.12231445313,0.170311347630828,5.53163699668587E-5
3748237905.771,50.1029853820801,-5600.0029296875,,
3748237981.7715,50.1026229858398,-5900.24560546875,0.164675021888677,5.72912367213659E-5
3748238047.7215,50.1035003662109,-6200.12231445313,0.162004469006488,4.9905509726963E-5
3748238113.734,50.1019229888916,-6499.99877929688,0.15959903260945,3.84464249234529E-5
3748238179.606,50.1022090911865,-6800.09814453125,0.156945738713689,5.23704946992063E-5
3748238245.605,50.1018943786621,-7100.0439453125,0.155219645538278,4.2757352163221E-5
3748238311.602,50.1025104522705,-7400.02661132813,0.15263386971445,3.6252574904129E-5
3748238377.477,50.1020202636719,-7700.220703125,0.151086381186622,3.79477487839043E-5
3748238443.4955,50.1019134521484,-8000.18701171875,0.149432275335953,4.76699671041154E-5
3748238522.905,50.103271484375,-8300.0234375,,
3748238588.3555,50.1051616668701,-8550.27783203125,0.146149697694718,4.62568406588716E-5
3748238654.2925,50.103630065918,-8850.23486328125,0.144542999757327,4.29221087732497E-5
3748238719.1785,50.1021575927734,-9150.32861328125,0.143421864710907,5.08119412916382E-5
3748238786.1225,50.1020736694336,-9450.06884765625,0.141979523280415,3.18204570699175E-5
3748238852.094,50.1022758483887,-9750.28857421875,0.140914627949051,4.79145829529258E-5
3748238918.028,50.1008548736572,-10050.1557617187,0.139448877851946,4.88138080090979E-5
3748238985.054,50.1015167236328,-10349.9926757813,0.138207329866539,2.97321880427698E-5
3748239050.9965,50.1018753051758,-10650.15234375,0.137497705560481,3.68114594300942E-5
3748239116.974,50.101016998291,-10950.4067382813,0.136759730481749,5.08591817931988E-5
3748239197.819,50.1039962768555,-11199.92578125,0.135641735636818,3.33533713695128E-5
3748239264.8,50.1037979125977,-11499.9609375,0.134177148027542,2.82583897659376E-5
3748239330.7055,50.1022815704346,-11800.1870117188,0.133347081613804,3.31768205537382E-5
3748239397.6635,50.1018352508545,-12099.9877929688,0.132682892491779,2.54547022011645E-5
3748239465.6505,50.1021099090576,-12400.189453125,0.131915040856994,3.64752317481511E-5
3748239531.7315,50.1037216186523,-12700.1557617188,0.130907129327485,4.06771138092049E-5
3748239598.6115,50.1022338867188,-12999.9794921875,0.129765202339453,2.66625180509641E-5
3748239665.4625,50.1023712158203,-13300.1762695313,0.129585981525524,3.22814436570675E-5
3748239732.5225,50.1025142669678,-13599.978515625,0.128387718788871,2.53791559598894E-5
3748239814.397,50.1050758361816,-13850.2622070312,0.128225347832931,3.36896281252456E-5
3748239880.34,50.1032180786133,-14150.177734375,0.127410138990478,3.39298570725305E-5
3748239947.3125,50.1038341522217,-14450.1333007813,0.126178822214902,2.88879411935942E-5
3748240013.2565,50.1024971008301,-14750.2578125,0.125971633057191,4.8461940562541E-5
3748240079.2455,50.1021327972412,-15050.060546875,0.125082837849928,3.10039632537284E-5
3748240146.1695,50.1020088195801,-15349.9477539062,0.124313929329474,4.33163930546529E-5
3748240212.178,50.1020488739014,-15650.234375,0.123628405881099,4.78919614508073E-5
3748240278.008,50.1022815704346,-15949.9985351562,0.122947656488927,3.2369083804818E-5
3748240344.993,50.1020069122314,-16250.2456054687,0.122674255161815,4.29773435564897E-5
3748240423.91,50.1044921875,-16500.00390625,0.122193445911323,3.29206759083065E-5
3748240492.878,50.1025142669678,-16800.0146484375,0.12137862708418,3.75626908446752E-5
3748240559.8775,50.1030406951904,-17100.2734375,0.120734428075907,5.56247041833214E-5
3748240627.798,50.1023960113525,-17400.1376953125,0.119665952609655,3.24104557765833E-5
3748240694.731,50.1018810272217,-17700.1513671875,0.11918133676752,3.85359144167544E-5
3748240763.606,50.1034049987793,-18000.3974609375,0.119253698093576,5.05074279579843E-5
3748240829.6225,50.1019420623779,-18300.05859375,0.118533540104463,2.8630447055021E-5
3748240895.603,50.1023597717285,-18600.3125,0.117885049970064,2.94252081763542E-5
3748240962.526,50.1026763916016,-18900.2880859375,0.116969290868511,4.42481796575095E-5
3748241042.446,50.105297088623,-19150.0634765625,0.116711429731978,4.21968357592805E-5
3748241109.433,50.1042633056641,-19449.9619140625,0.115923148251665,3.79220176024552E-5
3748241177.3375,50.1029434204102,-19750.0732421875,0.114226200462651,4.2196982545534E-5
3748241246.298,50.1025810241699,-20050.126953125,0.113702990534136,4.1926658590617E-5
3748241316.2805,50.1025505065918,-20350.1904296875,0.113746299064353,3.99235851582499E-5
3748241385.213,50.1023654937744,-20650.080078125,0.113241448496859,3.42856527836242E-5
3748241453.189,50.1023101806641,-20950.05078125,0.112895717703514,2.73941781435889E-5
3748241524.09,50.1027050018311,-21250.046875,0.111934764879837,3.98733940575708E-5
3748241590.9985,50.1021919250488,-21550.220703125,0.111882419372611,3.73895801490176E-5
3748241673.972,50.1052379608154,-21800.0927734375,0.111061931414718,2.90459490057389E-5
3748241742.917,50.1043891906738,-22100.1787109375,0.111248296638941,3.74914665681798E-5
3748241810.9755,50.1031951904297,-22400.013671875,0.109403848665762,4.14798633527151E-5
3748241880.8555,50.1044445037842,-22700.0732421875,0.110012091303006,3.60532792394945E-5
3748241949.779,50.1028785705566,-23000.0576171875,0.109269587884726,3.34774102060431E-5
3748242018.7345,50.1034927368164,-23300.04296875,0.108336539073347,3.26781107561892E-5
3748242086.7505,50.1034927368164,-23600.2880859375,0.108204053695917,3.74499106610298E-5
3748242156.6255,50.1026630401611,-23900.044921875,0.106960950479693,5.33124989659665E-5
3748242236.161,50.105339050293,-24200.029296875,,
3748242305.481,50.1063671112061,-24449.9814453125,0.106634164274946,4.51280438940556E-5
3748242374.4595,50.1044445037842,-24750.009765625,0.105477106850485,3.40308745589077E-5
3748242444.4235,50.1038837432861,-25050.125,0.105479994740229,5.77169299709268E-5
3748242513.3335,50.1028919219971,-25350.0263671875,0.104106562058085,4.0989537711366E-5
3748242581.2955,50.1033744812012,-25650.09375,0.104165104472386,4.80769862612017E-5
3748242651.2635,50.1040916442871,-25949.9677734375,0.103590170867552,2.84156917911153E-5
3748242721.167,50.1038703918457,-26250.02734375,0.103299233320744,2.61308121648815E-5
3748242790.127,50.1030750274658,-26550.087890625,0.102795283246274,5.24043118845247E-5
3748242871.0905,50.1013965606689,-26800.0029296875,0.0878614652933,4.78952099398179E-5
3748242939.009,50.106517791748,-27099.9658203125,0.101134970327628,4.44506633908253E-5
3748243006.994,50.1049098968506,-27400.3125,0.101538804465339,6.9516938557049E-5
3748243075.8655,50.104377746582,-27700.1943359375,0.10096071008357,3.98501689357791E-5
3748243144.8855,50.1047554016113,-27999.9091796875,0.100352678590139,4.02880404458458E-5
3748243214.8565,50.1044731140137,-28300.130859375,0.0991603871053459,3.5734663024483E-5
3748243284.772,50.103141784668,-28600.3671875,0.0989272531803015,2.95067789800196E-5
3748243353.7145,50.1036434173584,-28900.1708984375,0.0994824245069627,4.04832112052175E-5
3748243423.6625,50.1045322418213,-29200.0205078125,0.098221410420924,2.55557250821452E-5
3748243504.607,50.1067733764648,-29449.9755859375,0.0974719810960484,4.69244665307511E-5
3748243574.503,50.108247756958,-29750.173828125,0.09738484894039,3.38698089275837E-5
3748243644.482,50.1053047180176,-29949.98046875,0.0629067316488109,4.50759467267474E-5
3748243712.5965,50.1045989990234,-29650.0087890625,0.0284796388139451,5.5136630372185E-5
3748243802.511,50.1037616729736,-29349.9990234375,0.0255778792323267,4.56869573716457E-5
3748243891.484,50.1028671264648,-29050.021484375,0.0260494522968892,3.089222863247E-5
3748243981.405,50.103630065918,-28750.0166015625,0.0260570867731357,5.05051140681861E-5
3748244070.3965,50.1035308837891,-28449.9609375,0.0259748412294994,4.2754870340054E-5
3748244171.2725,50.1063022613525,-28200.0224609375,0.0264044957958693,4.54148766430002E-5
3748244261.171,50.1042461395264,-27899.9912109375,0.0265881310290453,3.74566988957161E-5
3748244350.219,50.1041927337646,-27600.052734375,0.0273174902588668,4.49438546736413E-5
3748244440.0255,50.1026401519775,-27300.06640625,0.0275466135226852,4.96714368744686E-5
3748244530.118,50.1034412384033,-26999.9892578125,0.0275950162198993,5.11730902791563E-5
3748244615.9445,50.1031360626221,-26700.0205078125,0.0281262345243181,4.37006734168065E-5
3748244718.083,50.1044425964355,-26400.001953125,,
3748244798.747,50.1049098968506,-26150.0234375,0.028653031041786,3.61620835005896E-5
3748244884.6985,50.1038341522217,-25849.99609375,0.0289817515824566,2.71079463957378E-5
3748244967.7685,50.1022758483887,-25550,0.0293409050455347,3.71405269850309E-5
3748245038.443,50.1029014587402,-25250.0029296875,0.0266690632268764,0.0001135359275766
3748245106.4165,50.1031894683838,-24950.130859375,0.028308620030829,5.37387599244733E-5
3748245175.356,50.1029987335205,-24649.9580078125,0.0286523068659189,6.61838234137083E-5
3748245244.327,50.1021747589111,-24349.9091796875,0.0275710165490054,0.000114496914658637
3748245312.2525,50.1022281646729,-24050.1162109375,0.0293950087840005,5.43470193221856E-5
3748245393.146,50.1042633056641,-23800.177734375,0.0288343488475993,8.03191739950457E-5
3748245460.114,50.1039237976074,-23499.9697265625,0.0286982133224344,0.000118726458716608
3748245527.1,50.1023235321045,-23200.0458984375,0.0310355079503979,5.737367542008E-5
3748245595.084,50.1020908355713,-22900.0361328125,0.0297718342842863,0.000119382257877358
3748245664.026,50.1026039123535,-22599.9765625,0.0307205775381329,7.96940113256548E-5
3748245731.9475,50.1015586853027,-22300.0478515625,0.0327144862394769,5.58428852106759E-5
3748245798.8415,50.1025695800781,-21999.955078125,0.0313144779253306,9.35944597329701E-5
3748245866.853,50.1022758483887,-21699.9951171875,0.0326357032863667,9.77167287571873E-5
3748245934.806,50.1020011901855,-21400.1396484375,0.0327570739977908,8.62259026449451E-5
3748246015.6635,50.1041927337646,-21149.91015625,0.0328868907685522,0.000105439320562389
3748246082.722,50.1037578582764,-20850.0927734375,0.0334578657779084,9.44517130729596E-5
3748246148.5855,50.1018505096436,-20550.2412109375,0.033917398296962,7.62051794133319E-5
3748246215.529,50.1018047332764,-20250.248046875,0.0347226409186613,5.64819953374343E-5
3748246281.559,50.1017570495605,-19950.150390625,0.0357176508721678,8.12985941718977E-5
3748246350.4625,50.1012306213379,-19650.27734375,0.0368616923308337,7.45010692173877E-5
3748246418.398,50.1010208129883,-19350.2548828125,0.0364428982894606,7.80029228171432E-5
3748246486.321,50.102388381958,-19050.150390625,0.0377260595664967,5.77653212940408E-5
3748246553.276,50.101188659668,-18749.9462890625,0.0379310461578902,7.71954729599972E-5
3748246632.266,50.1030158996582,-18500.1142578125,0.0388494227560663,7.49399421189709E-5
3748246698.212,50.1023960113525,-18200.0498046875,0.0381977000711584,0.000143046914141471
3748246766.193,50.1021156311035,-17900.0048828125,0.039735259867551,7.60474747593842E-5
3748246833.072,50.1020183563232,-17599.966796875,0.0412450687432212,5.80369493231976E-5
3748246901.012,50.1008243560791,-17300.0009765625,0.0412239506106447,7.44051887759241E-5
3748246968.0625,50.101224899292,-17000.07421875,0.0419838947050194,6.35059317408506E-5
3748247034.9565,50.1016597747803,-16699.9677734375,0.0433523167408839,4.76184658711922E-5
3748247098.85,50.1010456085205,-16399.7958984375,0.0439778997058995,7.03991336184212E-5
3748247165.875,50.1011066436768,-16100.1342773438,0.0437186861172042,7.34969954667554E-5
3748247243.757,50.1039257049561,-15850.21484375,0.0441212623387098,6.15910382254995E-5
3748247309.747,50.102222442627,-15550.2690429687,0.044899012098665,5.88481038338104E-5
3748247375.711,50.100866317749,-15249.982421875,0.0458404224333702,7.82766030760439E-5
3748247440.615,50.1005802154541,-14950.025390625,0.0477227055599862,7.28788094096834E-5
3748247505.572,50.1005611419678,-14650.04296875,0.0466936592540717,0.000117457406571625
3748247571.542,50.1007881164551,-14350.021484375,0.048402496752655,6.44826049533534E-5
3748247636.5525,50.0999393463135,-14050.0029296875,0.0488582130048046,7.69069021981045E-5
3748247702.4205,50.0996952056885,-13750.0341796875,0.0501283080389176,6.93634745289939E-5
3748247767.3685,50.1001491546631,-13450.0380859375,0.0503457120361732,7.7310940461663E-5
3748247848.3255,50.1019115447998,-13199.931640625,0.0512273496218766,7.50628234656524E-5
3748247915.3045,50.1021862030029,-12900.2080078125,0.052049817176754,5.32477442789811E-5
3748247982.2025,50.1007595062256,-12600.0219726563,0.0528056136693409,7.19567143479924E-5
3748248048.183,50.0999946594238,-12299.9682617188,0.0539235386774967,6.57549161324898E-5
3748248114.1495,50.100191116333,-12000.029296875,0.0541687491013017,7.01750670452702E-5
3748248181.0175,50.0994701385498,-11700.2309570312,0.0552314062197562,6.30894648290814E-5
3748248248.0445,50.1001739501953,-11399.9658203125,0.0570012716663162,4.89058965207758E-5
3748248313.9885,50.1010646820068,-11099.9443359375,0.0572866827381737,6.40947415603139E-5
3748248381.055,50.1002635955811,-10800.1206054688,0.0579478515043722,4.773410821934E-5
3748248459.9105,50.1010875701904,-10550.0947265625,0.0585302024662588,4.76802454873628E-5
3748248526.927,50.1005916595459,-10250.0087890625,0.059478489153802,6.30117904712463E-5
3748248592.7625,50.1000061035156,-9950.3603515625,0.0601420715977932,4.88944200023282E-5
3748248659.766,50.0999755859375,-9650.1318359375,0.0615012252944709,4.19479141847306E-5
3748248726.62,50.1005382537842,-9350.2529296875,0.0622479567565335,4.99316481990433E-5
3748248792.561,50.0998630523682,-9050.2607421875,0.0628026104566924,5.56449827476747E-5
3748248858.6175,50.0994319915771,-8750.16748046875,0.0639761721946377,4.85194007411709E-5
3748248924.489,50.1004238128662,-8450.1650390625,0.0648468476269371,4.53621429078747E-5
3748248990.5065,50.0989189147949,-8150.11352539063,0.0654438217742616,5.55930781625409E-5
3748249069.726,50.0973968505859,-7899.96752929688,0.0718657752352773,3.93560881577519E-5
3748249133.393,50.1010208129883,-7600.07958984375,0.0659745453078714,0.000105960393649712
3748249198.3295,50.1004772186279,-7300.19458007812,0.0678167025604399,5.30492876434491E-5
3748249264.253,50.0995349884033,-7000.13818359375,0.0688538883832643,5.13520886070498E-5
3748249329.181,50.0998210906982,-6700.11645507812,0.0697910127670491,4.57993516752022E-5
3748249394.152,50.098560333252,-6400.06323242188,0.0706975623832872,4.71161575335857E-5
3748249459.116,50.0989551544189,-6099.94213867187,0.070152328365251,0.000104003683605095
3748249524.0495,50.0999946594238,-5800.06787109375,0.0719587060192883,5.40906118154237E-5
3748249590.0415,50.0992603302002,-5499.99584960937,0.0730042886548048,5.08505497875392E-5
3748249655.9885,50.0979709625244,-5200.041015625,0.0733879965922048,5.82693346186841E-5
3748249735.88,50.1015777587891,-4950.21118164063,0.0734756659626338,5.67737444906539E-5
3748249800.8925,50.0996837615967,-4650.150390625,0.074598176163369,4.14457290406512E-5
3748249866.765,50.1035709381103,-4350.0224609375,0.0754428853740177,4.70228964184086E-5
3748249930.727,50.0990676879883,-4050.00573730469,0.0746997110824679,0.00010033566059996
3748249993.716,50.0984172821045,-3750.14099121094,0.076292924271938,4.99829434509398E-5
3748250056.6935,50.0986804962158,-3450.24621582031,0.0759700110591202,6.96740292647205E-5
3748250121.6215,50.0983772277832,-3150.11633300781,0.0768845248241039,5.07493615003005E-5
3748250183.616,50.0982608795166,-2850.21240234375,0.0757525995505628,9.38592561176916E-5
3748250245.5435,50.0988655090332,-2550.20947265625,0.074942645784581,0.000127627328694921
3748250320.5415,50.1009674072266,-2300.1328125,0.0748233406567141,0.000120640319691943
3748250380.482,50.1012897491455,-1999.99584960938,0.0741423195829372,0.000106651515498838
3748250440.385,50.1002941131592,-1699.93981933594,0.071435783427297,0.000155386084194713
3748250501.2995,50.099157333374,-1399.95062255859,0.0705115502409747,7.27088809892018E-5
3748250562.3705,50.0995407104492,-1099.87145996094,0.0637019187415834,0.00014636915380362
3748250622.235,50.0990028381348,-799.762451171875,0.0526464467624933,0.000258718367839763
3748250686.151,50.0979518890381,-500.003524780273,0.0355248428610459,9.22179987291375E-5
3748250761.4375,50.0982875823975,-199.945137023926,-0.0239306357564055,0.000107789397818679
3748250826.049,50.1008071899414,100.133991241455,-0.265319538421127,7.96681580906271E-5
3748250889.9985,50.0990924835205,400.150894165039,-0.461899880992161,0.000165599625526569
3748250969.951,50.1013679504395,650.1630859375,-0.426959704213576,0.000207482090755937
3748251032.9665,50.1002159118652,950.117706298828,-0.359548652480423,0.00016466512571487
3748251099.8195,50.0995597839355,1249.98034667969,-0.314097054471514,0.000132121139899535
3748251165.8535,50.0989665985107,1550.29681396484,-0.282647917481419,0.000127292012347661
3748251229.8435,50.1005554199219,1850.34826660156,-0.262435047384979,0.000197587690900694
3748251294.67,50.0990676879883,2150.20153808594,-0.242240821161949,8.42653295299917E-5
3748251360.619,50.097599029541,2450.20251464844,-0.228870362216275,8.54123653481559E-5
3748251425.632,50.1002998352051,2750.04431152344,-0.218010826569724,5.53443290356088E-5
3748251491.5315,50.0988903045654,3050.22924804687,-0.208930287813118,6.86084125612715E-5
3748251573.789,50.1006679534912,3300.08728027344,-0.201912909910148,6.05025511649798E-5
3748251642.861,50.0999717712402,3600.10412597656,-0.195308661187402,5.49820577797899E-5
3748251707.4435,50.0989837646484,3900.12329101562,-0.189216118715229,5.13447018570566E-5
3748251772.3485,50.098876953125,4200.23901367188,-0.183958539193038,4.89237934747315E-5
3748251838.3225,50.0988349914551,4500.13403320313,-0.179601630311449,3.71850787848798E-5
3748251904.2115,50.0980587005615,4800.326171875,-0.175835533208266,5.72875641434727E-5
3748251970.2215,50.0988483428955,5100.28100585937,-0.171556752221888,4.62865098906843E-5
3748252038.131,50.0989246368408,5400.02587890625,-0.168063786237918,3.29415941245201E-5
3748252104.1145,50.0984954833984,5700.28002929687,-0.16507593030636,4.82525597851389E-5
3748252184.03,50.0987396240234,5950.02709960937,-0.162991704395862,4.0670679453935E-5
3748252249.9735,50.1007633209229,6249.99365234375,-0.159925364220828,2.90736777429372E-5
3748252314.963,50.0996131896973,6550.19018554687,-0.157575473981013,3.89482495780104E-5
3748252380.887,50.0981369018555,6850.11450195313,-0.15488387938831,2.09387312707033E-5
3748252447.894,50.0980644226074,7150.04858398438,-0.1531321015032,2.72987772557929E-5
3748252514.7915,50.0975818634033,7450.46166992188,-0.15123619368488,5.08880261502916E-5
3748252581.857,50.0985679626465,7749.92138671875,-0.149095731748886,1.8860248929812E-5
3748252647.7535,50.0995178222656,8050.21484375,-0.147069007750898,3.74277045652626E-5
3748252714.662,50.0983219146729,8350.212890625,-0.145490292138095,3.3832309508364E-5
3748252793.8565,50.0963268280029,8599.955078125,-0.137973752636503,4.10791135792474E-5
3748252859.544,50.1011180877686,8900.28076171875,-0.142203226154338,3.44456831026094E-5
3748252927.462,50.1001205444336,9200.0126953125,-0.140463447003459,1.67571758464225E-5
3748252993.468,50.099308013916,9499.9677734375,-0.13927166635216,2.32892719965879E-5
3748253061.4155,50.0987815856934,9800.05615234375,-0.13792966997332,2.33546727953981E-5
3748253127.3445,50.0989246368408,10100.029296875,-0.136605654406869,2.21835838064343E-5
3748253193.2795,50.0978908538818,10400.2045898438,-0.135408024717471,2.64885527378991E-5
3748253261.268,50.0982513427734,10700.0375976562,-0.134484603544734,2.15937283625956E-5
3748253328.1595,50.0983352661133,11000.2915039062,-0.133327609663613,3.27586022743994E-5
3748253400.159,50.1008110046387,11249.9677734375,,
3748253479.0775,50.1004848480225,11550.1083984375,-0.131113759487042,2.49878808433885E-5
3748253548.002,50.0995693206787,11849.953125,-0.129929263608137,1.83179961760355E-5
3748253614.985,50.0989246368408,12150.02734375,-0.128735115713217,2.10806629053465E-5
3748253684.8855,50.101016998291,12450.1391601562,-0.128678836956669,2.12677071619293E-5
3748253751.9605,50.0985774993897,12749.9799804687,-0.127181491672591,2.42215193255369E-5
3748253819.8335,50.0990505218506,13050.0366210938,-0.126632904292231,2.23269748092887E-5
3748253887.851,50.0995178222656,13350.3159179688,-0.125706454925719,2.56828497617346E-5
3748253955.708,50.0995216369629,13649.9946289062,-0.124523482014114,2.80087537040259E-5
3748254038.667,50.1008071899414,13899.9555664062,-0.124373460070003,4.04533317255986E-5
3748254106.6685,50.1010456085205,14200.0805664062,-0.123583967635608,3.16413684331902E-5
3748254174.5285,50.0999164581299,14500.0581054687,-0.122283493387087,2.52169370465679E-5
3748254243.4515,50.1002807617188,14799.9985351562,-0.121431711051101,2.5913888013983E-5
3748254313.41,50.1001605987549,15099.9868164062,-0.121358190760596,2.5735119874216E-5
3748254382.3585,50.0990791320801,15400.0600585938,-0.12006697200122,2.23105428138431E-5
3748254452.38,50.0992126464844,15700.3100585938,-0.119774786436612,3.27459837656629E-5
3748254519.3285,50.0987396240234,16000.02734375,-0.119432909525714,2.5454073937161E-5
3748254589.301,50.0980777740479,16300.2680664062,-0.117897633661849,2.7151727912159E-5
3748254671.166,50.1022644042969,16549.966796875,-0.11775819790011,3.1706287456646E-5
3748254741.09,50.1010284423828,16850.2509765625,-0.117014584587616,2.98136377533976E-5
3748254811.1095,50.1004180908203,17150.1708984375,-0.116171175259262,2.38826299840667E-5
3748254881.03,50.0998687744141,17449.92578125,-0.114686348418713,1.92209860336767E-5
3748254949.0105,50.0995407104492,17750.34375,-0.115018367764096,2.86531285526871E-5
3748255017.958,50.0994567871094,18050.1015625,-0.113780101490743,3.45676607108687E-5
3748255087.897,50.0998401641846,18349.984375,-0.112772390734166,2.94679176318817E-5
3748255157.841,50.0993251800537,18650.12109375,-0.112690277199057,3.76970223361379E-5
3748255229.766,50.0996227264404,18950.107421875,-0.111867384651406,2.36193158266202E-5
3748255310.676,50.1017379760742,19200.064453125,-0.111422007706765,2.85965663047222E-5
3748255380.689,50.1009254455566,19500.0400390625,-0.111054166896032,3.00193189351336E-5
3748255449.633,50.1005973815918,19800.04296875,-0.109791906413295,3.21615859281272E-5
3748255520.502,50.0997734069824,20100.1123046875,-0.109306847459157,2.60325782325109E-5
3748255591.516,50.1006641387939,20400.0859375,-0.108596348370229,2.42286446344653E-5
3748255661.401,50.1021327972412,20699.953125,-0.108007127870779,2.26744691498472E-5
3748255732.3085,50.1000728607178,21000.0751953125,-0.10779390130812,2.60275087445087E-5
3748255802.3485,50.0993194580078,21299.884765625,-0.107453079744969,2.82085482616276E-5
3748255884.632,50.0984134674072,21549.9912109375,-0.0985417444024414,4.67410186886795E-5
3748255954.234,50.1018524169922,21850.1376953125,-0.105887692053261,2.62476972941263E-5
3748256026.153,50.1010990142822,22150.0185546875,-0.105566457664124,2.39550718905575E-5
3748256097.0265,50.1012191772461,22449.9482421875,-0.103761103024915,3.14175014546303E-5
3748256167.0365,50.1010036468506,22750.1953125,-0.103906031445475,2.89574132580223E-5
3748256235.9715,50.1004180908203,23049.8505859375,-0.103177329133772,3.56345033788601E-5
3748256305.967,50.1010875701904,23349.919921875,-0.102823009711183,2.62141718442422E-5
3748256376.8945,50.1003227233887,23649.923828125,-0.101680531758374,3.36784737257423E-5
3748256446.8245,50.1005249023438,23950.2333984375,-0.10165587506798,2.64472725111261E-5
3748256528.758,50.1022758483887,24200.0927734375,-0.101034044775639,3.45305355498993E-5
3748256599.692,50.1025276184082,24500.1416015625,-0.100436260112233,2.841526119621E-5
3748256670.7105,50.1020317077637,24800.1455078125,-0.0996521775641542,2.89673142734835E-5
3748256742.6595,50.1007118225098,25099.9921875,-0.0984344964164991,3.17183930847364E-5
3748256813.5225,50.1042823791504,25400.1162109375,-0.0982149264850793,3.66892988698605E-5
3748256884.485,50.1008014678955,25700.14453125,-0.0976477500335291,3.11260468131849E-5
3748256955.431,50.0997543334961,26000.1484375,-0.0965929061911326,4.04826953290835E-5
3748257027.389,50.0992832183838,26300.0751953125,-0.0961474144919244,2.89991599499011E-5
3748257111.403,50.101634979248,26600.001953125,,
3748257182.317,50.1021747589111,26850.0068359375,-0.0949801272286995,5.07109193306028E-5
3748257252.258,50.1019706726074,27150.6357421875,-0.0955591368806172,7.59969315822914E-5
3748257323.167,50.1013507843018,27449.7998046875,-0.0929214408854876,3.45001201720753E-5
3748257395.1875,50.1014633178711,27750.3017578125,-0.0932398638318328,3.41800883962814E-5
3748257466.0395,50.1011524200439,28049.8564453125,-0.0923677930108995,3.41864104937097E-5
3748257538.018,50.1005973815918,28350.1318359375,-0.0920773331483963,5.05334873734556E-5
3748257609.9265,50.1001434326172,28649.8603515625,-0.0911212440388468,3.45221752087391E-5
3748257681.944,50.1015644073486,28949.8798828125,-0.0902636853500938,4.13045351325678E-5
3748257764.842,50.1040210723877,29200.171875,-0.0902693084946061,3.26144914459511E-5
3748257835.811,50.1029376983643,29500.134765625,-0.0900190094122017,3.36936202887323E-5
3748257906.724,50.1014099121094,29799.7900390625,-0.0883205337941529,3.87379258735347E-5
3748257954.704,50.1024723052978,30000.0966796875,-0.0892455139213006,4.02575942632589E-5